"""
Whatever exception occurs in the try block - you can simply handle the exception in the Except block.

"""

try:
    a = 0/0
except:
    print ("Exception Handled!")